Workbook

Sheet 真實IC
A1: Real
B2: Time | C2: 2013/12 | D2: 2014/01 | E2: 2014/02 | F2: 2014/03 | G2: 2014/04 | H2: 2014/05 | I2: 2014/06 | J2: 2014/07 | K2: 2014/08 | L2: 2014/09 | M2: 2014/10 | N2: 2014/11 | O2: 2014/12 | P2: 2015/01 | Q2: 2015/02 | R2: 2015/03 | S2: 2015/04 | T2: 2015/05 | U2: 2015/06 | V2: 2015/07 | W2: 2015/08 | X2: 2015/09 | Y2: 2015/10 | Z2: 2015/11 | AA2: 2015/12 | AB2: 2016/01 | AC2: 2016/02 | AD2: 2016/03 | AE2: 2016/04 | AF2: 2016/05 | AG2: 2016/06 | AH2: 2016/07 | AI2: 2016/08 | AJ2: 2016/09 | AK2: 2016/10 | AL2: 2016/11 | AM2: 2016/12 | AN2: 2017/01 | AO2: 2017/02 | AP2: 2017/03 | AQ2: 2017/04 | AR2: 2017/05 | AS2: 2017/06 | AT2: 2017/07 | AU2: 2017/08 | AV2: 2017/09 | AW2: 2017/10 | AX2: 2017/11 | AY2: 2017/12 | AZ2: 2018/01 | BA2: 2018/02 | BB2: 2018/03 | BC2: 2018/04 | BD2: 2018/05 | BE2: 2018/06 | BF2: 2018/07 | BG2: 2018/08 | BH2: 2018/09 | BI2: 2018/10 | BJ2: 2018/11 | BK2: 2018/12 | BL2: 2019/01 | BM2: 2019/02 | BN2: 2019/03 | BO2: 2019/04 | BP2: 2019/05 | BQ2: 2019/06 | BR2: 2019/07 | BS2: 2019/08 | BT2: 2019/09 | BU2: 2019/10 | BV2: 2019/11 | BW2: 2019/12 | BX2: 2020/01 | BY2: 2020/02 | BZ2: 2020/03 | CA2: 2020/04 | CB2: 2020/05 | CC2: 2020/06 | CD2: 2020/07 | CE2: 2020/08 | CF2: 2020/09 | CG2: 2020/10 | CH2: 2020/11 | CI2: 2020/12 | CJ2: 2021/01 | CK2: 2021/02 | CL2: 2021/03 | CM2: 2021/04 | CN2: 2021/05 | CO2: 2021/06 | CP2: 2021/07 | CQ2: 2021/08 | CR2: 2021/09 | CS2: 2021/10 | CT2: 2021/11 | CU2: 2021/12 | CV2: 2022/01 | CW2: 2022/02 | CX2: 2022/03 | CY2: 2022/04 | CZ2: 2022/05 | DA2: 2022/06 | DB2: 2022/07 | DC2: 2022/08 | DD2: 2022/09 | DE2: 2022/10 | DF2: 2022/11 | DG2: 2022/12 | DH2: 2023/01 | DI2: 2023/02 | DJ2: 2023/03 | DK2: 2023/04 | DL2: 2023/05 | DM2: 2023/06 | DN2: 2023/07 | DO2: 2023/08 | DP2: 2023/09 | DQ2: 2023/10 | DR2: 2023/11 | DS2: 2023/12 | DT2: 2024/01 | DU2: 2024/02 | DV2: 2024/03 | DW2: 2024/04 | DX2: 2024/05 | DY2: 2024/06 | DZ2: 2024/07 | EA2: 2024/08 | EB2: 2024/09 | EC2: 2024/10 | ED2: 2024/11 | EE2: 2024/12 | EF2: 2025/01
B3: bm | C3: 0.10910583 | D3: 0.014576583 | E3: -0.036154357 | F3: -0.004742601 | G3: -0.0057477531 | H3: 0.049378023 | I3: 0.18325177 | J3: 0.11648631 | K3: -0.030594946 | L3: 0.019828051 | M3: -0.020999006 | N3: 0.14977942 | O3: 0.015463406 | P3: -0.091792321 | Q3: -0.077409013 | R3: 0.054776596 | S3: -0.12533439 | T3: -0.11905342 | U3: -0.037770051 | V3: 0.081183823 | W3: 0.084008968 | X3: 0.14701136 | Y3: -0.12536054 | Z3: 0.19195355 | AA3: -0.084370782 | AB3: 0.072897614 | AC3: 0.10260456 | AD3: 0.015770167 | AE3: -0.15200716 | AF3: 0.059250252 | AG3: 0.13005884 | AH3: 0.1152564 | AI3: 0.032606622 | AJ3: 0.027999115 | AK3: 0.14657042 | AL3: 0.040841921 | AM3: 0.13137637 | AN3: 0.22143296 | AO3: -0.020941039 | AP3: -0.13715995 | AQ3: -0.024882855 | AR3: 0.015513971 | AS3: 0.034373037 | AT3: 0.063095686 | AU3: 0.043237695 | AV3: -0.074230367 | AW3: 0.027994827 | AX3: 0.11986442 | AY3: 0.076559571 | AZ3: -0.021730386 | BA3: -0.0012464633 | BB3: 0.10099582 | BC3: 0.02982693 | BD3: 0.0086757684 | BE3: 0.068557206 | BF3: 0.1569126 | BG3: 0.15920373 | BH3: 0.061121668 | BI3: 0.096912851 | BJ3: -0.054746248 | BK3: -0.087492963 | BL3: 0.094426746 | BM3: -0.022191059 | BN3: 0.015628612 | BO3: 0.08141824 | BP3: -0.018508942 | BQ3: 0.068729568 | BR3: 0.0031023605 | BS3: 0.074964418 | BT3: 0.045201588 | BU3: 0.025677329 | BV3: 0.091804031 | BW3: -0.026353999 | BX3: 0.019394832 | BY3: -0.076838899 | BZ3: 0.11330931 | CA3: -0.10735493 | CB3: 0.040844789 | CC3: -0.019801709 | CD3: 0.18837709 | CE3: 0.055574906 | CF3: 0.074872074 | CG3: 0.10000019 | CH3: 0.13602172 | CI3: -0.093741015 | CJ3: 0.0039305991 | CK3: 0.056507777 | CL3: 0.26354578 | CM3: -0.0095554349 | CN3: -0.0315119 | CO3: -0.022619032 | CP3: 0.13265561 | CQ3: 0.13307278 | CR3: -0.014956408 | CS3: -0.033419938 | CT3: 0.012281209 | CU3: 0.11681498 | CV3: -0.0031589454 | CW3: 0.038217758 | CX3: 0.13917409 | CY3: -0.023712288 | CZ3: 0.21835291 | DA3: -0.057967362 | DB3: -0.014104219 | DC3: 0.11395608 | DD3: 0.074472262 | DE3: -0.00089969275 | DF3: 0.0009770718 | DG3: -0.072980095 | DH3: -0.023845287 | DI3: -0.10153067 | DJ3: 0.027692536 | DK3: -0.049335153 | DL3: -0.0056993576 | DM3: -0.03698176 | DN3: 0.10981299 | DO3: 0.042036825 | DP3: 0.084566668 | DQ3: -0.11027981 | DR3: 0.094328709 | DS3: -0.071906913 | DT3: -0.09623643 | DU3: 0.0023455494 | DV3: 0.13401742 | DW3: 0.094732519 | DX3: -0.1037732 | DY3: 0.075762154 | DZ3: -0.03182972 | EA3: 0.16130802 | EB3: 0.010203533 | EC3: 0.073988425 | ED3: -0.15737687 | EE3: 0.079137553 | EF3: 0.072528547
B4: size | C4: -0.24758871 | D4: -0.2746933 | E4: -0.084648385 | F4: 0.022644631 | G4: -0.049680001 | H4: -0.10075963 | I4: -0.012522721 | J4: 0.07873655 | K4: -0.0341851 | L4: 0.088406798 | M4: -0.0030634546 | N4: -0.21221799 | O4: -0.036805389 | P4: 0.071033119 | Q4: -0.071261133 | R4: 0.021560447 | S4: 0.10111126 | T4: 0.04322474 | U4: 0.01488195 | V4: 0.0063260243 | W4: -0.14355298 | X4: -0.064282172 | Y4: -0.019034203 | Z4: -0.020644556 | AA4: 0.03305954 | AB4: -0.019418227 | AC4: -0.063126839 | AD4: -0.065629712 | AE4: 0.13799569 | AF4: -0.10056792 | AG4: -0.037969091 | AH4: -0.045839538 | AI4: -0.051034096 | AJ4: -0.0032204409 | AK4: 0.00048952959 | AL4: -0.10644675 | AM4: -0.013723974 | AN4: -0.12196471 | AO4: -0.048589666 | AP4: -0.0019031504 | AQ4: 0.029067485 | AR4: 0.052635777 | AS4: -0.012893259 | AT4: -0.0021311348 | AU4: -0.15538438 | AV4: 0.012681784 | AW4: -0.011942322 | AX4: -0.0042537915 | AY4: 0.029300872 | AZ4: -0.1341275 | BA4: -0.13711153 | BB4: 0.0017546605 | BC4: 0.025117126 | BD4: -0.11960191 | BE4: 0.13576165 | BF4: 0.047091162 | BG4: -0.026050044 | BH4: 0.043752774 | BI4: -0.081391828 | BJ4: -0.10060082 | BK4: 0.090490079 | BL4: -0.030898459 | BM4: 0.058814187 | BN4: 0.081345639 | BO4: -0.0077164169 | BP4: 0.10673487 | BQ4: -0.027156341 | BR4: -0.054431019 | BS4: -0.068229278 | BT4: 0.098612223 | BU4: 0.12839854 | BV4: -0.078402519 | BW4: -0.11913372 | BX4: -0.046890096 | BY4: 0.10169834 | BZ4: -0.025680084 | CA4: -0.08330179 | CB4: -0.15782765 | CC4: -0.071052572 | CD4: -0.073875492 | CE4: -0.23678647 | CF4: 0.032627706 | CG4: 0.013423085 | CH4: -0.0027966659 | CI4: 0.0479257 | CJ4: -0.0032520193 | CK4: -0.07570819 | CL4: -0.044397256 | CM4: 0.17898858 | CN4: 0.057994266 | CO4: -0.13939019 | CP4: 0.064714671 | CQ4: -0.18118789 | CR4: -0.088633532 | CS4: -0.025321775 | CT4: -0.11307907 | CU4: 0.0080959573 | CV4: -0.045200208 | CW4: -0.058941225 | CX4: -0.1077283 | CY4: -0.096503499 | CZ4: -0.21035435 | DA4: -0.10996114 | DB4: -0.19082047 | DC4: -0.020727272 | DD4: 0.087029095 | DE4: 0.082024593 | DF4: -0.16687666 | DG4: 0.22243809 | DH4: -0.14429775 | DI4: -0.11961995 | DJ4: -0.10159274 | DK4: 0.092855059 | DL4: -0.04263049 | DM4: 0.082732073 | DN4: -0.031049452 | DO4: -0.09814199 | DP4: -0.13058888 | DQ4: 0.048655718 | DR4: -0.03925191 | DS4: -0.1610302 | DT4: -0.078883966 | DU4: 0.16407716 | DV4: 0.0075052515 | DW4: -0.10164525 | DX4: -0.056040292 | DY4: -0.10665664 | DZ4: -0.069186576 | EA4: -0.12618866 | EB4: -0.064737118 | EC4: 0.051426073 | ED4: 0.034496728 | EE4: 0.1576776 | EF4: -0.12718002
B5: mom | C5: 0.12739768 | D5: 0.27252583 | E5: 0.062930306 | F5: -0.14734515 | G5: -0.034796316 | H5: -0.17085566 | I5: 0.29079019 | J5: -0.051821723 | K5: -0.23905237 | L5: 0.16620736 | M5: -0.072210617 | N5: -0.42337901 | O5: -0.29069667 | P5: -0.14041748 | Q5: 0.23352851 | R5: 0.16517753 | S5: 0.12715404 | T5: 0.099032464 | U5: -0.15685697 | V5: 0.34240724 | W5: -0.0046833913 | X5: -0.25395648 | Y5: -0.20123386 | Z5: -0.11123074 | AA5: 0.0021490845 | AB5: -0.26829032 | AC5: -0.21172288 | AD5: 0.064383544 | AE5: 0.14496488 | AF5: 0.18985456 | AG5: -0.032297318 | AH5: -0.082731792 | AI5: 0.16109736 | AJ5: 0.030692207 | AK5: 0.095896478 | AL5: 0.33781955 | AM5: -0.13593222 | AN5: -0.082413428 | AO5: -0.0053739832 | AP5: 0.013199201 | AQ5: -0.23614839 | AR5: -0.058600174 | AS5: 0.16395218 | AT5: 0.038405682 | AU5: 0.17193844 | AV5: -0.16562523 | AW5: 0.17323637 | AX5: 0.15002837 | AY5: -0.13718978 | AZ5: 0.15902436 | BA5: -0.1190889 | BB5: 0.12623528 | BC5: -0.065959479 | BD5: 0.038041275 | BE5: 0.21160919 | BF5: 0.21764732 | BG5: -0.0216843 | BH5: 0.13545461 | BI5: 0.068235801 | BJ5: 0.073730186 | BK5: -0.29588165 | BL5: -0.059953299 | BM5: 0.23395341 | BN5: 0.018383136 | BO5: -0.21905668 | BP5: 0.17599541 | BQ5: 0.057650745 | BR5: 0.093172811 | BS5: 0.052167629 | BT5: 0.15210362 | BU5: -0.085801272 | BV5: -0.042133721 | BW5: -0.021311745 | BX5: 0.17120792 | BY5: -0.080485095 | BZ5: -0.12364829 | CA5: -0.074301521 | CB5: 0.12073194 | CC5: 0.06025877 | CD5: 0.022957324 | CE5: -0.0026733186 | CF5: 0.012598263 | CG5: -0.022713292 | CH5: -0.050643866 | CI5: 0.072246051 | CJ5: -0.084576469 | CK5: -0.10637609 | CL5: 0.071926224 | CM5: 0.11061768 | CN5: 0.064087005 | CO5: -0.062058839 | CP5: 0.036804237 | CQ5: -0.25493009 | CR5: -0.16652197 | CS5: -0.027255068 | CT5: -0.13520774 | CU5: 0.027837995 | CV5: 0.012629131 | CW5: -0.034961229 | CX5: 0.0066480736 | CY5: 0.14353743 | CZ5: -0.096973778 | DA5: -0.11326111 | DB5: 0.14997042 | DC5: -0.029730317 | DD5: 0.26841149 | DE5: -0.2061103 | DF5: -0.0043307064 | DG5: -0.20048169 | DH5: -0.35622362 | DI5: -0.20326487 | DJ5: -0.097865021 | DK5: 0.054606508 | DL5: 0.10053554 | DM5: -0.046529544 | DN5: -0.042009117 | DO5: -0.21185988 | DP5: -0.007589212 | DQ5: 0.09490759 | DR5: -0.18405621 | DS5: 0.0063254967 | DT5: 0.059951171 | DU5: -0.073780223 | DV5: -0.11215628 | DW5: -0.093047073 | DX5: 0.035421025 | DY5: -0.024769289 | DZ5: 0.029984228 | EA5: -0.024212077 | EB5: -0.068635333 | EC5: -0.0061714037 | ED5: -0.078157858 | EE5: 0.0001305871 | EF5: 0.042088954
A6: 選絕對值最大 | C6: 2 | D6: 2 | E6: 2 | F6: 3 | G6: 2 | H6: 3 | I6: 3 | J6: 1 | K6: 3 | L6: 3 | M6: 3 | N6: 3 | O6: 3 | P6: 3 | Q6: 3 | R6: 3 | S6: 3 | T6: 1 | U6: 3 | V6: 3 | W6: 2 | X6: 3 | Y6: 3 | Z6: 1 | AA6: 1 | AB6: 3 | AC6: 3 | AD6: 2 | AE6: 1 | AF6: 3 | AG6: 1 | AH6: 1 | AI6: 3 | AJ6: 3 | AK6: 1 | AL6: 3 | AM6: 3 | AN6: 1 | AO6: 2 | AP6: 1 | AQ6: 3 | AR6: 3 | AS6: 3 | AT6: 1 | AU6: 3 | AV6: 3 | AW6: 3 | AX6: 3 | AY6: 3 | AZ6: 3 | BA6: 2 | BB6: 3 | BC6: 3 | BD6: 2 | BE6: 3 | BF6: 3 | BG6: 1 | BH6: 3 | BI6: 1 | BJ6: 2 | BK6: 3 | BL6: 1 | BM6: 3 | BN6: 2 | BO6: 3 | BP6: 3 | BQ6: 1 | BR6: 3 | BS6: 1 | BT6: 3 | BU6: 2 | BV6: 1 | BW6: 2 | BX6: 3 | BY6: 2 | BZ6: 3 | CA6: 1 | CB6: 2 | CC6: 2 | CD6: 1 | CE6: 2 | CF6: 1 | CG6: 1 | CH6: 1 | CI6: 1 | CJ6: 3 | CK6: 3 | CL6: 1 | CM6: 2 | CN6: 3 | CO6: 2 | CP6: 1 | CQ6: 3 | CR6: 3 | CS6: 1 | CT6: 3 | CU6: 1 | CV6: 2 | CW6: 2 | CX6: 1 | CY6: 3 | CZ6: 1 | DA6: 3 | DB6: 2 | DC6: 1 | DD6: 3 | DE6: 3 | DF6: 2 | DG6: 2 | DH6: 3 | DI6: 3 | DJ6: 2 | DK6: 2 | DL6: 3 | DM6: 2 | DN6: 1 | DO6: 3 | DP6: 2 | DQ6: 1 | DR6: 3 | DS6: 2 | DT6: 1 | DU6: 2 | DV6: 1 | DW6: 2 | DX6: 1 | DY6: 2 | DZ6: 2 | EA6: 1 | EB6: 3 | EC6: 1 | ED6: 1 | EE6: 2 | EF6: 2
C7: size | D7: size | E7: size | F7: mom | G7: size | H7: mom | I7: mom | J7: bm | K7: mom | L7: mom | M7: mom | N7: mom | O7: mom | P7: mom | Q7: mom | R7: mom | S7: mom | T7: bm | U7: mom | V7: mom | W7: size | X7: mom | Y7: mom | Z7: bm | AA7: bm | AB7: mom | AC7: mom | AD7: size | AE7: bm | AF7: mom | AG7: bm | AH7: bm | AI7: mom | AJ7: mom | AK7: bm | AL7: mom | AM7: mom | AN7: bm | AO7: size | AP7: bm | AQ7: mom | AR7: mom | AS7: mom | AT7: bm | AU7: mom | AV7: mom | AW7: mom | AX7: mom | AY7: mom | AZ7: mom | BA7: size | BB7: mom | BC7: mom | BD7: size | BE7: mom | BF7: mom | BG7: bm | BH7: mom | BI7: bm | BJ7: size | BK7: mom | BL7: bm | BM7: mom | BN7: size | BO7: mom | BP7: mom | BQ7: bm | BR7: mom | BS7: bm | BT7: mom | BU7: size | BV7: bm | BW7: size | BX7: mom | BY7: size | BZ7: mom | CA7: bm | CB7: size | CC7: size | CD7: bm | CE7: size | CF7: bm | CG7: bm | CH7: bm | CI7: bm | CJ7: mom | CK7: mom | CL7: bm | CM7: size | CN7: mom | CO7: size | CP7: bm | CQ7: mom | CR7: mom | CS7: bm | CT7: mom | CU7: bm | CV7: size | CW7: size | CX7: bm | CY7: mom | CZ7: bm | DA7: mom | DB7: size | DC7: bm | DD7: mom | DE7: mom | DF7: size | DG7: size | DH7: mom | DI7: mom | DJ7: size | DK7: size | DL7: mom | DM7: size | DN7: bm | DO7: mom | DP7: size | DQ7: bm | DR7: mom | DS7: size | DT7: bm | DU7: size | DV7: bm | DW7: size | DX7: bm | DY7: size | DZ7: size | EA7: bm | EB7: mom | EC7: bm | ED7: bm | EE7: size | EF7: size
C8: -0.24758871 | D8: -0.2746933 | E8: -0.084648385 | F8: -0.14734515 | G8: -0.049680001 | H8: -0.17085566 | I8: 0.29079019 | J8: 0.11648631 | K8: -0.23905237 | L8: 0.16620736 | M8: -0.072210617 | N8: -0.42337901 | O8: -0.29069667 | P8: -0.14041748 | Q8: 0.23352851 | R8: 0.16517753 | S8: 0.12715404 | T8: -0.11905342 | U8: -0.15685697 | V8: 0.34240724 | W8: -0.14355298 | X8: -0.25395648 | Y8: -0.20123386 | Z8: 0.19195355 | AA8: -0.084370782 | AB8: -0.26829032 | AC8: -0.21172288 | AD8: -0.065629712 | AE8: -0.15200716 | AF8: 0.18985456 | AG8: 0.13005884 | AH8: 0.1152564 | AI8: 0.16109736 | AJ8: 0.030692207 | AK8: 0.14657042 | AL8: 0.33781955 | AM8: -0.13593222 | AN8: 0.22143296 | AO8: -0.048589666 | AP8: -0.13715995 | AQ8: -0.23614839 | AR8: -0.058600174 | AS8: 0.16395218 | AT8: 0.063095686 | AU8: 0.17193844 | AV8: -0.16562523 | AW8: 0.17323637 | AX8: 0.15002837 | AY8: -0.13718978 | AZ8: 0.15902436 | BA8: -0.13711153 | BB8: 0.12623528 | BC8: -0.065959479 | BD8: -0.11960191 | BE8: 0.21160919 | BF8: 0.21764732 | BG8: 0.15920373 | BH8: 0.13545461 | BI8: 0.096912851 | BJ8: -0.10060082 | BK8: -0.29588165 | BL8: 0.094426746 | BM8: 0.23395341 | BN8: 0.081345639 | BO8: -0.21905668 | BP8: 0.17599541 | BQ8: 0.068729568 | BR8: 0.093172811 | BS8: 0.074964418 | BT8: 0.15210362 | BU8: 0.12839854 | BV8: 0.091804031 | BW8: -0.11913372 | BX8: 0.17120792 | BY8: 0.10169834 | BZ8: -0.12364829 | CA8: -0.10735493 | CB8: -0.15782765 | CC8: -0.071052572 | CD8: 0.18837709 | CE8: -0.23678647 | CF8: 0.074872074 | CG8: 0.10000019 | CH8: 0.13602172 | CI8: -0.093741015 | CJ8: -0.084576469 | CK8: -0.10637609 | CL8: 0.26354578 | CM8: 0.17898858 | CN8: 0.064087005 | CO8: -0.13939019 | CP8: 0.13265561 | CQ8: -0.25493009 | CR8: -0.16652197 | CS8: -0.033419938 | CT8: -0.13520774 | CU8: 0.11681498 | CV8: -0.045200208 | CW8: -0.058941225 | CX8: 0.13917409 | CY8: 0.14353743 | CZ8: 0.21835291 | DA8: -0.11326111 | DB8: -0.19082047 | DC8: 0.11395608 | DD8: 0.26841149 | DE8: -0.2061103 | DF8: -0.16687666 | DG8: 0.22243809 | DH8: -0.35622362 | DI8: -0.20326487 | DJ8: -0.10159274 | DK8: 0.092855059 | DL8: 0.10053554 | DM8: 0.082732073 | DN8: 0.10981299 | DO8: -0.21185988 | DP8: -0.13058888 | DQ8: -0.11027981 | DR8: -0.18405621 | DS8: -0.1610302 | DT8: -0.09623643 | DU8: 0.16407716 | DV8: 0.13401742 | DW8: -0.10164525 | DX8: -0.1037732 | DY8: -0.10665664 | DZ8: -0.069186576 | EA8: 0.16130802 | EB8: -0.068635333 | EC8: 0.073988425 | ED8: -0.15737687 | EE8: 0.1576776 | EF8: -0.12718002
A10: 投資組合 | C10: 公司數 | D10: 964
A11: 等分 | B11: 家數 | C11: 2014/01 | D11: 2014/02 | E11: 2014/03 | F11: 2014/04 | G11: 2014/05 | H11: 2014/06 | I11: 2014/07 | J11: 2014/08 | K11: 2014/09 | L11: 2014/10 | M11: 2014/11 | N11: 2014/12 | O11: 2015/01 | P11: 2015/02 | Q11: 2015/03 | R11: 2015/04 | S11: 2015/05 | T11: 2015/06 | U11: 2015/07 | V11: 2015/08 | W11: 2015/09 | X11: 2015/10 | Y11: 2015/11 | Z11: 2015/12 | AA11: 2016/01 | AB11: 2016/02 | AC11: 2016/03 | AD11: 2016/04 | AE11: 2016/05 | AF11: 2016/06 | AG11: 2016/07 | AH11: 2016/08 | AI11: 2016/09 | AJ11: 2016/10 | AK11: 2016/11 | AL11: 2016/12 | AM11: 2017/01 | AN11: 2017/02 | AO11: 2017/03 | AP11: 2017/04 | AQ11: 2017/05 | AR11: 2017/06 | AS11: 2017/07 | AT11: 2017/08 | AU11: 2017/09 | AV11: 2017/10 | AW11: 2017/11 | AX11: 2017/12 | AY11: 2018/01 | AZ11: 2018/02 | BA11: 2018/03 | BB11: 2018/04 | BC11: 2018/05 | BD11: 2018/06 | BE11: 2018/07 | BF11: 2018/08 | BG11: 2018/09 | BH11: 2018/10 | BI11: 2018/11 | BJ11: 2018/12 | BK11: 2019/01 | BL11: 2019/02 | BM11: 2019/03 | BN11: 2019/04 | BO11: 2019/05 | BP11: 2019/06 | BQ11: 2019/07 | BR11: 2019/08 | BS11: 2019/09 | BT11: 2019/10 | BU11: 2019/11 | BV11: 2019/12 | BW11: 2020/01 | BX11: 2020/02 | BY11: 2020/03 | BZ11: 2020/04 | CA11: 2020/05 | CB11: 2020/06 | CC11: 2020/07 | CD11: 2020/08 | CE11: 2020/09 | CF11: 2020/10 | CG11: 2020/11 | CH11: 2020/12 | CI11: 2021/01 | CJ11: 2021/02 | CK11: 2021/03 | CL11: 2021/04 | CM11: 2021/05 | CN11: 2021/06 | CO11: 2021/07 | CP11: 2021/08 | CQ11: 2021/09 | CR11: 2021/10 | CS11: 2021/11 | CT11: 2021/12 | CU11: 2022/01 | CV11: 2022/02 | CW11: 2022/03 | CX11: 2022/04 | CY11: 2022/05 | CZ11: 2022/06 | DA11: 2022/07 | DB11: 2022/08 | DC11: 2022/09 | DD11: 2022/10 | DE11: 2022/11 | DF11: 2022/12 | DG11: 2023/01 | DH11: 2023/02 | DI11: 2023/03 | DJ11: 2023/04 | DK11: 2023/05 | DL11: 2023/06 | DM11: 2023/07 | DN11: 2023/08 | DO11: 2023/09 | DP11: 2023/10 | DQ11: 2023/11 | DR11: 2023/12 | DS11: 2024/01 | DT11: 2024/02 | DU11: 2024/03 | DV11: 2024/04 | DW11: 2024/05 | DX11: 2024/06 | DY11: 2024/07 | DZ11: 2024/08 | EA11: 2024/09 | EB11: 2024/10 | EC11: 2024/11 | ED11: 2024/12 | EE11: 2025/01 | EF11: 2025/02
A12: 10 | B12: 96 | C12: 0.08669241 | D12: 0.11417438 | E12: 0.05158948 | F12: 0.05595938 | G12: 0.01518301 | H12: -0.00959926 | I12: -0.00865815 | J12: 0.04240914 | K12: -0.029188 | L12: 0.00875856 | M12: -0.02688917 | N12: 0.03470335 | O12: -0.02791476 | P12: 0.00025433 | Q12: 0.0041954 | R12: 0.01280542 | S12: 0.01105503 | T12: 0.04340357 | U12: 0.00135652 | V12: 0.0096554 | W12: 0.06403941 | X12: 0.10892036 | Y12: -0.02049478 | Z12: 0.06493404 | AA12: 0.03863679 | AB12: -0.01073333 | AC12: 0.04677295 | AD12: 0.00939224 | AE12: 0.03774651 | AF12: -0.0520121 | AG12: 0.03089537 | AH12: 0.01407318 | AI12: 0.00879379 | AJ12: -0.02103366 | AK12: 0.04817399 | AL12: -0.04489094 | AM12: -0.01973838 | AN12: 0.06928955 | AO12: 0.01170404 | AP12: 0.03139715 | AQ12: 0.00169693 | AR12: -0.02222303 | AS12: 0.01997627 | AT12: 0.01321936 | AU12: 0.00371354 | AV12: -0.05371563 | AW12: 0.0171697 | AX12: -0.04384826 | AY12: -0.01690956 | AZ12: -0.02361455 | BA12: 0.07127616 | BB12: -0.02903665 | BC12: -0.02669097 | BD12: 0.04923362 | BE12: -0.03536855 | BF12: -0.06761695 | BG12: 0.03382252 | BH12: -0.03507959 | BI12: 0.05097313 | BJ12: 0.0434225 | BK12: 0.00065738 | BL12: 0.02470925 | BM12: 0.05030568 | BN12: 0.01950254 | BO12: 0.00249404 | BP12: 0.0151588 | BQ12: 0.01533947 | BR12: 0.06869362 | BS12: 0.01862442 | BT12: 0.01636478 | BU12: 0.04808337 | BV12: 0.03034928 | BW12: 0.05548756 | BX12: -0.00698515 | BY12: 0.04581599 | BZ12: -0.03237873 | CA12: 0.03158368 | CB12: 0.07247588 | CC12: 0.06556661 | CD12: 0.10772592 | CE12: 0.15400701 | CF12: 0.02516457 | CG12: 0.04167925 | CH12: 0.06646705 | CI12: 0.03511917 | CJ12: -0.05412007 | CK12: -0.05610144 | CL12: 0.11801561 | CM12: 0.07061391 | CN12: 0.0784652 | CO12: 0.07137327 | CP12: 0.04519343 | CQ12: 0.06268435 | CR12: 0.05715999 | CS12: 0.01520165 | CT12: 0.00932906 | CU12: 0.03334614 | CV12: 0.00463158 | CW12: 0.02936667 | CX12: 0.06098988 | CY12: 0.0164206 | CZ12: 0.07930253 | DA12: -0.01682433 | DB12: 0.09016464 | DC12: 0.03447259 | DD12: -0.06996055 | DE12: 0.02473764 | DF12: 0.05542041 | DG12: 0.04624092 | DH12: -0.03080316 | DI12: -0.02997925 | DJ12: 0.01542829 | DK12: 0.03079659 | DL12: 0.01866983 | DM12: 0.01970281 | DN12: 0.03912576 | DO12: 0.01903073 | DP12: 0.04846012 | DQ12: 0.02255058 | DR12: 0.01085205 | DS12: 0.07013771 | DT12: 0.04295136 | DU12: 0.05712811 | DV12: 0.05258831 | DW12: 0.04496125 | DX12: 0.05024951 | DY12: 0.05281902 | DZ12: 0.00655929 | EA12: 0.06425958 | EB12: 0.03052578 | EC12: 0.02665151 | ED12: 0.05770915 | EE12: 0.02591775 | EF12: 0.02901453
A13: 20 | B13: 48 | C13: 0.10411275 | D13: 0.12374503 | E13: 0.06986156 | F13: 0.05998653 | G13: 0.01799323 | H13: -0.01738839 | I13: 0.03228599 | J13: 0.03765853 | K13: -0.06032614 | L13: 0.02198047 | M13: -0.00327976 | N13: 0.04339242 | O13: -0.0174227 | P13: 0.00627765 | Q13: -0.01745638 | R13: 0.01651071 | S13: -0.0060138 | T13: 0.0502519 | U13: -0.02876133 | V13: 0.00221664 | W13: 0.07547656 | X13: 0.12312815 | Y13: 0.00668336 | Z13: 0.07287805 | AA13: 0.03368103 | AB13: -0.01500157 | AC13: 0.0667717 | AD13: 0.02154369 | AE13: 0.04379824 | AF13: -0.07328116 | AG13: 0.03168178 | AH13: 0.01068719 | AI13: 0.01864605 | AJ13: -0.00170745 | AK13: 0.06598791 | AL13: -0.04656453 | AM13: 0.00768004 | AN13: 0.10524544 | AO13: 0.00302041 | AP13: 0.0583617 | AQ13: 0.00234007 | AR13: -0.02084804 | AS13: 0.02340496 | AT13: 0.04046309 | AU13: -0.01569542 | AV13: -0.07966598 | AW13: 0.02682124 | AX13: -0.02838278 | AY13: -0.01146735 | AZ13: -0.03122054 | BA13: 0.07982912 | BB13: -0.0225474 | BC13: -0.01911087 | BD13: 0.04167631 | BE13: -0.04377379 | BF13: -0.12165714 | BG13: 0.04139871 | BH13: -0.04102366 | BI13: 0.05240913 | BJ13: 0.05145192 | BK13: 0.0088784 | BL13: 0.03194786 | BM13: 0.05337177 | BN13: -0.00410154 | BO13: 0.0044924 | BP13: 0.01845625 | BQ13: 0.04270743 | BR13: 0.07983146 | BS13: 0.00756975 | BT13: 0.00052107 | BU13: 0.07465817 | BV13: 0.02934981 | BW13: 0.08623015 | BX13: -0.00074564 | BY13: 0.03082776 | BZ13: -0.06597673 | CA13: 0.03238228 | CB13: 0.12042697 | CC13: 0.12011817 | CD13: 0.10623144 | CE13: 0.18382784 | CF13: 0.04560016 | CG13: 0.03900046 | CH13: 0.05833461 | CI13: 0.05185351 | CJ13: -0.05481018 | CK13: -0.06568713 | CL13: 0.07837308 | CM13: 0.10145222 | CN13: 0.10099417 | CO13: 0.08556624 | CP13: 0.06972654 | CQ13: 0.07117886 | CR13: 0.11164489 | CS13: -0.01197031 | CT13: -0.00040854 | CU13: 0.0381492 | CV13: 0.02431898 | CW13: 0.01045696 | CX13: 0.06077974 | CY13: 0.04120175 | CZ13: 0.05722422 | DA13: -0.01693663 | DB13: 0.10623532 | DC13: 0.02977557 | DD13: -0.06897706 | DE13: 0.022442 | DF13: 0.08312219 | DG13: 0.04772908 | DH13: -0.03880652 | DI13: -0.02957042 | DJ13: 0.00598358 | DK13: 0.01938663 | DL13: 0.02205069 | DM13: -0.00053162 | DN13: 0.0148398 | DO13: 0.04432514 | DP13: 0.04499715 | DQ13: 0.02643008 | DR13: 0.01446696 | DS13: 0.06859685 | DT13: 0.0354263 | DU13: 0.03460772 | DV13: 0.07962014 | DW13: 0.04325803 | DX13: 0.06464192 | DY13: 0.05101728 | DZ13: 0.03012492 | EA13: 0.0766312 | EB13: 0.05720529 | EC13: 0.04165975 | ED13: 0.06568209 | EE13: 0.04062502 | EF13: 0.04259039
A14: 50 | B14: 19 | C14: 0.11994149 | D14: 0.22230845 | E14: 0.09876825 | F14: 0.0603419 | G14: 0.08514876 | H14: 0.01150826 | I14: 0.03010014 | J14: 0.01441091 | K14: -0.05082747 | L14: 0.05627108 | M14: 0.01902171 | N14: 0.05736943 | O14: -0.00149441 | P14: -0.00654142 | Q14: -0.07929766 | R14: -0.01776231 | S14: -0.02480675 | T14: 0.06984148 | U14: -0.03055617 | V14: -0.0524213 | W14: 0.11616579 | X14: 0.1866857 | Y14: 0.05519099 | Z14: 0.0456464 | AA14: 0.03945018 | AB14: -0.02733598 | AC14: -0.00308656 | AD14: 0.03932789 | AE14: 0.10743434 | AF14: -0.0960801 | AG14: 0.02052089 | AH14: 0.00525028 | AI14: -0.03546264 | AJ14: 0.02450558 | AK14: 0.07106183 | AL14: -0.05123018 | AM14: 0.00537089 | AN14: 0.09787823 | AO14: -0.00999865 | AP14: 0.07054608 | AQ14: -0.02973338 | AR14: -0.00758269 | AS14: -0.00666934 | AT14: 0.0144197 | AU14: -0.05742161 | AV14: -0.06625875 | AW14: 0.05392868 | AX14: -0.01032761 | AY14: -0.00169057 | AZ14: -0.06107058 | BA14: 0.09633733 | BB14: -0.11031125 | BC14: 0.02850568 | BD14: 0.04349692 | BE14: -0.07008177 | BF14: -0.15382926 | BG14: 0.04137426 | BH14: -0.07341346 | BI14: 0.05018521 | BJ14: 0.02401693 | BK14: 0.03369142 | BL14: 0.05973777 | BM14: 0.04627833 | BN14: -0.04537171 | BO14: 0.01323824 | BP14: 0.01733685 | BQ14: 0.01584352 | BR14: 0.10005242 | BS14: -0.04097084 | BT14: -0.03072648 | BU14: 0.11136102 | BV14: 0.0238989 | BW14: 0.11840804 | BX14: 0.0143353 | BY14: 0.08039977 | BZ14: -0.09337468 | CA14: 0.02446527 | CB14: 0.1644655 | CC14: 0.12059616 | CD14: 0.08716938 | CE14: 0.1705553 | CF14: 0.09233068 | CG14: 0.05306703 | CH14: 0.06466139 | CI14: 0.10588478 | CJ14: -0.01779612 | CK14: -0.05379209 | CL14: 0.06226995 | CM14: 0.11006897 | CN14: 0.17459567 | CO14: 0.17324915 | CP14: 0.09980933 | CQ14: 0.0322279 | CR14: 0.20771971 | CS14: -0.05902712 | CT14: 0.00966189 | CU14: -0.04357201 | CV14: 0.03939943 | CW14: 0.008234 | CX14: 0.0362719 | CY14: 0.09636113 | CZ14: 0.06406356 | DA14: 0.05635188 | DB14: 0.10460744 | DC14: 0.02363261 | DD14: -0.07920535 | DE14: 0.06252692 | DF14: 0.20156284 | DG14: 0.0455834 | DH14: -0.00841324 | DI14: -0.04065913 | DJ14: 0.01589759 | DK14: 0.08162155 | DL14: 0.04075487 | DM14: 0.00112115 | DN14: 0.03985171 | DO14: 0.07028855 | DP14: 0.00361786 | DQ14: 0.08936786 | DR14: 0.0054841 | DS14: 0.05605182 | DT14: 0.04451695 | DU14: 0.06879527 | DV14: 0.10826235 | DW14: 0.00180931 | DX14: 0.10216122 | DY14: 0.0742587 | DZ14: 0.035031 | EA14: 0.07810527 | EB14: 0.07817983 | EC14: 0.00607938 | ED14: 0.09887025 | EE14: -0.00339925 | EF14: 0.02552536
A15: 100 | B15: 10 | C15: 0.22764466 | D15: 0.37270922 | E15: 0.06603849 | F15: -0.03492144 | G15: 0.09660559 | H15: 0.00124373 | I15: 0.07929309 | J15: 0.04269185 | K15: -0.0945148 | L15: 0.08117106 | M15: 0.00213302 | N15: 0.10979619 | O15: 0.0122708 | P15: -0.02189657 | Q15: -0.04589873 | R15: -0.12669106 | S15: 0.08548789 | T15: 0.06680012 | U15: -0.07819939 | V15: -0.11012701 | W15: 0.10693456 | X15: 0.21118633 | Y15: 0.0520288 | Z15: 0.04671997 | AA15: 0.05126801 | AB15: -0.0221664 | AC15: 0.00431767 | AD15: 0.03969048 | AE15: 0.10131332 | AF15: -0.13772629 | AG15: 0.02044227 | AH15: -0.03710418 | AI15: -0.02484926 | AJ15: 0.03371792 | AK15: 0.06175962 | AL15: -0.03236017 | AM15: 0.04702644 | AN15: 0.09286191 | AO15: 0.03570184 | AP15: 0.08645777 | AQ15: -0.03645332 | AR15: -0.01773383 | AS15: -0.04873322 | AT15: 0.06525499 | AU15: -0.07717408 | AV15: -0.03729793 | AW15: 0.09172747 | AX15: -0.06427588 | AY15: -0.02900566 | AZ15: -0.06784633 | BA15: 0.15768795 | BB15: -0.19771315 | BC15: 0.03093669 | BD15: 0.00759201 | BE15: -0.04139797 | BF15: -0.21087209 | BG15: 0.00282482 | BH15: -0.09864905 | BI15: 0.06858666 | BJ15: 0.0751539 | BK15: -0.04560493 | BL15: 0.06274818 | BM15: 0.048219 | BN15: -0.06605404 | BO15: -0.06955561 | BP15: -0.01086316 | BQ15: 0.01280293 | BR15: 0.12376214 | BS15: -0.01682378 | BT15: -0.05985094 | BU15: 0.08554573 | BV15: 0.05922894 | BW15: 0.20414584 | BX15: 0.05385157 | BY15: 0.09333839 | BZ15: -0.20472002 | CA15: 0.01859202 | CB15: 0.1310914 | CC15: 0.17365171 | CD15: 0.10234801 | CE15: 0.07336812 | CF15: 0.09846999 | CG15: -0.00429888 | CH15: 0.06288596 | CI15: 0.02780307 | CJ15: -0.04067172 | CK15: -0.09564075 | CL15: 0.03142197 | CM15: 0.10811976 | CN15: 0.14314982 | CO15: 0.17335999 | CP15: 0.12753584 | CQ15: -0.02496336 | CR15: 0.18148893 | CS15: -0.06018517 | CT15: -0.00494167 | CU15: -0.06317866 | CV15: 0.0604445 | CW15: -0.02725744 | CX15: 0.02403961 | CY15: 0.0929479 | CZ15: 0.07988695 | DA15: -0.05788215 | DB15: 0.09704824 | DC15: 0.02482111 | DD15: -0.01450673 | DE15: 0.05716363 | DF15: 0.30272045 | DG15: 0.04791748 | DH15: 0.00093841 | DI15: -0.05410832 | DJ15: 0.04756662 | DK15: 0.10032893 | DL15: -0.00030399 | DM15: -0.00177326 | DN15: 0.0439965 | DO15: 0.03410442 | DP15: -0.04033019 | DQ15: 0.09504091 | DR15: -0.03047264 | DS15: 0.03753014 | DT15: 0.07216363 | DU15: 0.11712765 | DV15: 0.13421062 | DW15: -0.06082633 | DX15: 0.11861625 | DY15: 0.14360957 | DZ15: 0.04045565 | EA15: 0.02749364 | EB15: 0.08808745 | EC15: 0.06190947 | ED15: 0.11335706 | EE15: 0.00319072 | EF15: 0.02964606
A16: 107 | B16: 9 | C16: 0.20787478 | D16: 0.40819498 | E16: 0.06500658 | F16: -0.07871547 | G16: 0.10901251 | H16: 0.00064935 | I16: 0.10921796 | J16: 0.04670993 | K16: -0.08642089 | L16: 0.0851616 | M16: 0.01398744 | N16: 0.1202425 | O16: 0.02858708 | P16: -0.00818818 | Q16: -0.08147864 | R16: -0.10310969 | S16: 0.10985904 | T16: 0.06721906 | U16: -0.09147193 | V16: -0.07557149 | W16: 0.07837349 | X16: 0.24053196 | Y16: 0.05027883 | Z16: 0.03403977 | AA16: 0.04348764 | AB16: -0.03229541 | AC16: -0.01276545 | AD16: 0.03481117 | AE16: 0.09650236 | AF16: -0.14791561 | AG16: 0.01329075 | AH16: -0.0317654 | AI16: -0.03338326 | AJ16: 0.04812048 | AK16: 0.0644214 | AL16: -0.0054397 | AM16: 0.05214573 | AN16: 0.1064562 | AO16: 0.04004267 | AP16: 0.07779837 | AQ16: -0.05449775 | AR16: -0.03437198 | AS16: -0.05264272 | AT16: 0.04954716 | AU16: -0.08209027 | AV16: -0.05208084 | AW16: 0.10898494 | AX16: -0.07724101 | AY16: -0.01960185 | AZ16: -0.08815018 | BA16: 0.1599907 | BB16: -0.22547356 | BC16: 0.03899939 | BD16: 0.00628218 | BE16: -0.06119764 | BF16: -0.24778686 | BG16: 0.0122014 | BH16: -0.09616203 | BI16: 0.05233576 | BJ16: 0.08142812 | BK16: -0.05137162 | BL16: 0.07062357 | BM16: 0.03949799 | BN16: -0.06719797 | BO16: -0.07421686 | BP16: -0.01345824 | BQ16: 0.01647802 | BR16: 0.13058297 | BS16: -0.01987319 | BT16: -0.04666088 | BU16: 0.09186151 | BV16: 0.0567357 | BW16: 0.22394491 | BX16: 0.06655952 | BY16: 0.11899471 | BZ16: -0.13158185 | CA16: 0.02971439 | CB16: 0.13930874 | CC16: 0.04438815 | CD16: 0.15507127 | CE16: 0.09361423 | CF16: 0.10520126 | CG16: -0.00537852 | CH16: 0.04169741 | CI16: 0.03870988 | CJ16: -0.02970339 | CK16: -0.08842269 | CL16: 0.01846278 | CM16: 0.11305584 | CN16: 0.16035992 | CO16: 0.20954752 | CP16: 0.13663169 | CQ16: -0.02033378 | CR16: 0.18928653 | CS16: -0.06655916 | CT16: -0.02555738 | CU16: -0.06343465 | CV16: 0.05945399 | CW16: -0.03167311 | CX16: 0.01224028 | CY16: 0.08128064 | CZ16: 0.10263326 | DA16: -0.0781063 | DB16: 0.09801728 | DC16: 0.03535772 | DD16: -0.03174371 | DE16: 0.0345524 | DF16: 0.32557955 | DG16: 0.04567692 | DH16: -0.00397883 | DI16: -0.0453995 | DJ16: 0.05175322 | DK16: 0.09625462 | DL16: -0.02187287 | DM16: -0.038135 | DN16: 0.04243785 | DO16: 0.04656387 | DP16: -0.02471658 | DQ16: 0.08303366 | DR16: -0.06830538 | DS16: 0.02144067 | DT16: 0.10053413 | DU16: 0.12277205 | DV16: 0.13695373 | DW16: -0.07130257 | DX16: 0.12528471 | DY16: 0.15757213 | DZ16: 0.05881075 | EA16: 0.04666137 | EB16: 0.1006791 | EC16: 0.06353207 | ED16: 0.11541675 | EE16: 0.00439668 | EF16: 0.03455064
A17: 120 | B17: 8 | C17: 0.20609219 | D17: 0.43958849 | E17: 0.07958985 | F17: -0.08075216 | G17: 0.11713148 | H17: -0.00794286 | I17: 0.11307752 | J17: 0.05243602 | K17: -0.10156008 | L17: 0.04223479 | M17: -0.01465914 | N17: 0.10927783 | O17: 0.01130668 | P17: -0.01338295 | Q17: -0.10026683 | R17: -0.13642645 | S17: 0.11905439 | T17: 0.06761646 | U17: -0.0624059 | V17: -0.09725966 | W17: 0.07914199 | X17: 0.23798943 | Y17: 0.07362313 | Z17: 0.04372306 | AA17: 0.03520979 | AB17: -0.0445383 | AC17: -0.02008625 | AD17: 0.06861982 | AE17: 0.12715842 | AF17: -0.12028632 | AG17: 0.02274098 | AH17: -0.03547262 | AI17: -0.05703798 | AJ17: 0.06161262 | AK17: 0.07371627 | AL17: -0.02701818 | AM17: 0.09335171 | AN17: 0.11328712 | AO17: 0.03070403 | AP17: 0.07887378 | AQ17: -0.06127725 | AR17: -0.04580263 | AS17: -0.05880296 | AT17: 0.05226781 | AU17: -0.11569961 | AV17: -0.05852945 | AW17: 0.07618961 | AX17: -0.07252933 | AY17: -0.01547805 | AZ17: -0.07049423 | BA17: 0.16280641 | BB17: -0.23044204 | BC17: 0.02729282 | BD17: 0.01941187 | BE17: -0.04411025 | BF17: -0.14777683 | BG17: -0.03539424 | BH17: -0.13319111 | BI17: 0.09936539 | BJ17: 0.08919148 | BK17: -0.01675133 | BL17: 0.07748297 | BM17: 0.02905901 | BN17: -0.07365677 | BO17: -0.0850873 | BP17: 0.00031058 | BQ17: 0.01137651 | BR17: 0.11502235 | BS17: -0.00410347 | BT17: -0.05265016 | BU17: 0.1045243 | BV17: 0.06228267 | BW17: 0.22723409 | BX17: 0.08264099 | BY17: 0.09586087 | BZ17: -0.06685753 | CA17: 0.02793483 | CB17: 0.14963316 | CC17: 0.04176025 | CD17: 0.17022985 | CE17: 0.09570807 | CF17: 0.0987462 | CG17: -0.00871775 | CH17: 0.05863645 | CI17: 0.01453118 | CJ17: -0.02095083 | CK17: -0.08395585 | CL17: -0.01115051 | CM17: 0.09549387 | CN17: 0.17653128 | CO17: 0.19808042 | CP17: 0.14815927 | CQ17: 0.0519071 | CR17: 0.19640263 | CS17: -0.09684163 | CT17: -0.01733928 | CU17: -0.07440831 | CV17: 0.06789102 | CW17: -0.02315584 | CX17: 0.01077239 | CY17: 0.07560891 | CZ17: 0.12424884 | DA17: -0.0481098 | DB17: 0.10427163 | DC17: 0.04336347 | DD17: -0.02915542 | DE17: 0.02412486 | DF17: 0.35222555 | DG17: 0.04721099 | DH17: -0.01265389 | DI17: -0.03504454 | DJ17: 0.0571465 | DK17: 0.10278127 | DL17: -0.00392973 | DM17: -0.04256361 | DN17: 0.03548903 | DO17: 0.06525054 | DP17: -0.02509743 | DQ17: 0.10770247 | DR17: -0.04543126 | DS17: 0.03735409 | DT17: 0.09398021 | DU17: 0.12949296 | DV17: 0.11907757 | DW17: -0.07659891 | DX17: 0.12953898 | DY17: 0.1072829 | DZ17: 0.04921263 | EA17: 0.01181792 | EB17: 0.10728533 | EC17: 0.01642522 | ED17: 0.12832444 | EE17: -0.00019352 | EF17: 0.04098721
A18: 137 | B18: 7 | C18: 0.18975112 | D18: 0.40188368 | E18: 0.05343935 | F18: -0.11938296 | G18: 0.13305806 | H18: -0.00862223 | I18: 0.12862656 | J18: 0.04341152 | K18: -0.13564789 | L18: 0.05075821 | M18: -0.02905146 | N18: 0.14120749 | O18: -0.03173794 | P18: -0.00832809 | Q18: -0.09305959 | R18: -0.15418919 | S18: 0.14380523 | T18: 0.0526381 | U18: -0.05515034 | V18: -0.12139146 | W18: 0.07729628 | X18: 0.21512106 | Y18: 0.10387924 | Z18: 0.08923436 | AA18: 0.04170525 | AB18: -0.06264481 | AC18: 0.00136542 | AD18: 0.09628585 | AE18: 0.14352924 | AF18: -0.15054364 | AG18: 0.01574367 | AH18: -0.04019746 | AI18: -0.08142375 | AJ18: 0.07086722 | AK18: 0.04570256 | AL18: -0.03281281 | AM18: 0.09605303 | AN18: 0.11682605 | AO18: 0.04666895 | AP18: 0.08502876 | AQ18: -0.06415497 | AR18: -0.03900247 | AS18: -0.08325313 | AT18: 0.04332565 | AU18: -0.13889821 | AV18: -0.06023566 | AW18: 0.09776686 | AX18: -0.11340549 | AY18: -0.03018936 | AZ18: -0.05164633 | BA18: 0.18047976 | BB18: -0.31745743 | BC18: -0.02794205 | BD18: 0.02027514 | BE18: -0.09117285 | BF18: -0.16498649 | BG18: -0.01680624 | BH18: -0.13789827 | BI18: 0.10900001 | BJ18: 0.09953152 | BK18: -0.00098108 | BL18: 0.08115767 | BM18: 0.02808136 | BN18: -0.0782087 | BO18: -0.06216908 | BP18: 0.00845134 | BQ18: 0.01890528 | BR18: 0.12096182 | BS18: -0.0131139 | BT18: -0.06154532 | BU18: 0.11146155 | BV18: 0.07052164 | BW18: 0.26103993 | BX18: 0.07458086 | BY18: 0.06268674 | BZ18: -0.03534765 | CA18: 0.01607654 | CB18: 0.10684606 | CC18: 0.10466062 | CD18: 0.19371682 | CE18: 0.07726039 | CF18: 0.07181759 | CG18: -0.0083364 | CH18: 0.16265705 | CI18: 0.03886914 | CJ18: 0.00377237 | CK18: -0.09605803 | CL18: -0.03098955 | CM18: 0.10276961 | CN18: 0.12094313 | CO18: 0.22828209 | CP18: 0.16283911 | CQ18: 0.03824268 | CR18: 0.19372241 | CS18: -0.07802725 | CT18: 0.01627249 | CU18: -0.07164869 | CV18: 0.06294462 | CW18: -0.02832826 | CX18: 0.06156019 | CY18: 0.09317838 | CZ18: 0.13284286 | DA18: -0.07689055 | DB18: 0.11811472 | DC18: 0.03640878 | DD18: -0.04101419 | DE18: 0.03842059 | DF18: 0.36669201 | DG18: 0.05477048 | DH18: -0.01305003 | DI18: -0.01861325 | DJ18: 0.05065451 | DK18: 0.10652726 | DL18: -0.00383027 | DM18: -0.05845716 | DN18: -0.01672206 | DO18: 0.03019902 | DP18: -0.02151033 | DQ18: 0.10072728 | DR18: -0.05246106 | DS18: 0.01127798 | DT18: 0.11601739 | DU18: 0.15871482 | DV18: 0.10564061 | DW18: -0.06863695 | DX18: 0.15360298 | DY18: 0.13683311 | DZ18: 0.05463037 | EA18: -0.00636156 | EB18: 0.10996435 | EC18: 0.00276412 | ED18: 0.11047802 | EE18: 0.00111129 | EF18: 0.06395433
A19: 160 | B19: 6 | C19: 0.19660027 | D19: 0.40752071 | E19: 0.06581421 | F19: -0.17768866 | G19: 0.15286434 | H19: 0.01206879 | I19: 0.13411218 | J19: 0.03542958 | K19: -0.23878941 | L19: 0.02032665 | M19: 0.04369024 | N19: 0.15184358 | O19: -0.03156187 | P19: -0.02351316 | Q19: -0.08186611 | R19: -0.14558327 | S19: 0.12269188 | T19: 0.02528021 | U19: -0.06725 | V19: -0.09268832 | W19: 0.07241557 | X19: 0.14939987 | Y19: 0.10313024 | Z19: 0.09161911 | AA19: 0.02329 | AB19: -0.05171875 | AC19: 0.01414154 | AD19: 0.09599338 | AE19: 0.16941606 | AF19: -0.16883058 | AG19: 0.0025952 | AH19: -0.05655772 | AI19: -0.04776635 | AJ19: 0.07720271 | AK19: 0.00755204 | AL19: -0.01491461 | AM19: 0.06112413 | AN19: 0.08356829 | AO19: 0.05774641 | AP19: 0.08757412 | AQ19: -0.04237567 | AR19: 0.04114451 | AS19: -0.10919888 | AT19: 0.04929498 | AU19: -0.15301463 | AV19: 0.00303261 | AW19: 0.1366934 | AX19: -0.14007951 | AY19: -0.06627324 | AZ19: -0.11561153 | BA19: 0.18699678 | BB19: -0.36416093 | BC19: -0.18457179 | BD19: -7.371e-05 | BE19: -0.08948072 | BF19: -0.14180943 | BG19: -0.01634366 | BH19: -0.14049691 | BI19: 0.12779863 | BJ19: 0.05181931 | BK19: 0.06951904 | BL19: 0.09159567 | BM19: 0.03178626 | BN19: -0.08141326 | BO19: -0.10556468 | BP19: -0.00281414 | BQ19: 0.00993404 | BR19: 0.13683924 | BS19: -0.02425634 | BT19: -0.0823234 | BU19: 0.13067063 | BV19: 0.09365524 | BW19: 0.2959763 | BX19: 0.05483028 | BY19: 0.02767549 | BZ19: -0.00342503 | CA19: 0.02932876 | CB19: 0.12783821 | CC19: 0.02250623 | CD19: 0.2156192 | CE19: 0.08847486 | CF19: 0.0799044 | CG19: -0.05063353 | CH19: 0.15288987 | CI19: 0.03706695 | CJ19: 0.01181192 | CK19: -0.11879726 | CL19: -0.04324028 | CM19: 0.11023588 | CN19: 0.14319321 | CO19: 0.25123563 | CP19: 0.1590326 | CQ19: 0.03239461 | CR19: 0.17630672 | CS19: -0.06070085 | CT19: 0.02794064 | CU19: -0.0834364 | CV19: 0.07614249 | CW19: -0.03219213 | CX19: 0.05763473 | CY19: 0.10789212 | CZ19: 0.11285183 | DA19: -0.1196964 | DB19: 0.14796185 | DC19: -0.0351794 | DD19: -0.00620113 | DE19: 0.03301841 | DF19: 0.20550175 | DG19: 0.06637426 | DH19: -0.04322061 | DI19: -0.05864703 | DJ19: 0.0804996 | DK19: 0.12144231 | DL19: -0.01198279 | DM19: -0.05730043 | DN19: 0.00247512 | DO19: 0.04870552 | DP19: -0.00400246 | DQ19: 0.12048938 | DR19: -0.03318106 | DS19: -0.00567731 | DT19: 0.1331285 | DU19: 0.15058192 | DV19: 0.11953184 | DW19: -0.10129597 | DX19: 0.13836513 | DY19: 0.13924868 | DZ19: 0.07853795 | EA19: -0.02807935 | EB19: 0.10875351 | EC19: -0.00830183 | ED19: 0.15093532 | EE19: -0.00730653 | EF19: 0.07402292
A20: 192 | B20: 5 | C20: 0.20155105 | D20: 0.38202502 | E20: 0.05733635 | F20: -0.20553126 | G20: 0.15802736 | H20: -0.01158303 | I20: 0.18586318 | J20: 0.03447126 | K20: -0.2147245 | L20: 0.00899977 | M20: 0.07771823 | N20: 0.16814359 | O20: -0.04986489 | P20: -0.04313868 | Q20: -0.10704532 | R20: -0.19094247 | S20: 0.08256261 | T20: -0.01566291 | U20: -0.01372036 | V20: -0.1035176 | W20: 0.09108487 | X20: 0.21038641 | Y20: 0.12896504 | Z20: 0.10561696 | AA20: 0.02159455 | AB20: -0.03289855 | AC20: 0.04724826 | AD20: 0.12984342 | AE20: 0.17528151 | AF20: -0.22349782 | AG20: 0.02765922 | AH20: -0.0901782 | AI20: -0.08327935 | AJ20: 0.06072568 | AK20: -0.01359512 | AL20: -0.02078027 | AM20: 0.06752986 | AN20: 0.0645854 | AO20: 0.06808546 | AP20: 0.11055597 | AQ20: -0.03330823 | AR20: 0.029739 | AS20: -0.04229172 | AT20: 0.00585877 | AU20: -0.14307264 | AV20: 0.03224661 | AW20: 0.22499784 | AX20: -0.20433922 | AY20: 0.08205764 | AZ20: -0.15627401 | BA20: 0.15133773 | BB20: -0.37844679 | BC20: -0.24014067 | BD20: 0.00836017 | BE20: -0.09827837 | BF20: -0.13797126 | BG20: 0.00378214 | BH20: -0.1500573 | BI20: 0.16438674 | BJ20: 0.05515592 | BK20: 0.10259828 | BL20: 0.08629223 | BM20: 0.04746855 | BN20: 0.01863803 | BO20: -0.13121844 | BP20: -0.01525946 | BQ20: 0.01545171 | BR20: 0.18112708 | BS20: 0.00540751 | BT20: -0.0965305 | BU20: 0.149441 | BV20: 0.11591833 | BW20: 0.34204268 | BX20: 0.05798802 | BY20: 0.04318348 | BZ20: -0.00572006 | CA20: 0.0113335 | CB20: 0.12649505 | CC20: 0.01291515 | CD20: 0.1810275 | CE20: 0.08577817 | CF20: 0.08095794 | CG20: -0.09905289 | CH20: 0.07186403 | CI20: 0.03039467 | CJ20: 0.04150998 | CK20: -0.08058962 | CL20: -0.09218493 | CM20: 0.09677581 | CN20: 0.20489183 | CO20: 0.29657331 | CP20: 0.19203121 | CQ20: 0.02311805 | CR20: 0.19548611 | CS20: -0.08836428 | CT20: 0.01807671 | CU20: -0.09486766 | CV20: 0.09700395 | CW20: -0.0258164 | CX20: 0.09029855 | CY20: 0.10096666 | CZ20: 0.15516165 | DA20: -0.22461946 | DB20: 0.07696807 | DC20: -0.03315031 | DD20: -0.00359718 | DE20: 0.01041872 | DF20: 0.24557421 | DG20: 0.05234481 | DH20: -0.04805841 | DI20: -0.07424834 | DJ20: 0.08127702 | DK20: 0.08518754 | DL20: -0.01946537 | DM20: -0.06933611 | DN20: 0.05801921 | DO20: 0.04982085 | DP20: -0.02167126 | DQ20: 0.16561708 | DR20: -0.08820888 | DS20: -0.0074907 | DT20: 0.13343598 | DU20: 0.17637517 | DV20: 0.12934547 | DW20: -0.10354617 | DX20: 0.15386633 | DY20: 0.12159146 | DZ20: 0.09019965 | EA20: 0.01491703 | EB20: 0.08240714 | EC20: 0.03404958 | ED20: 0.17691886 | EE20: -0.00174098 | EF20: 0.08580306
A21: 241 | B21: 4 | C21: 0.21462958 | D21: 0.12638792 | E21: -0.01369017 | F21: -0.18403858 | G21: 0.14533186 | H21: 0.03784408 | I21: 0.23932306 | J21: 0.06043533 | K21: -0.20688003 | L21: 0.05722617 | M21: 0.09968459 | N21: 0.13905068 | O21: -0.03435199 | P21: -0.03989172 | Q21: -0.08119537 | R21: -0.14269209 | S21: 0.20915948 | T21: 0.01404036 | U21: 0.08021574 | V21: -0.10537077 | W21: 0.12449862 | X21: 0.21363094 | Y21: 0.09272922 | Z21: 0.11420399 | AA21: -0.01949104 | AB21: -0.02195594 | AC21: 0.01882774 | AD21: 0.12882467 | AE21: 0.24045611 | AF21: -0.29514426 | AG21: 0.04430278 | AH21: -0.11420601 | AI21: -0.06772968 | AJ21: 0.07894116 | AK21: -0.03580317 | AL21: -0.03739149 | AM21: -0.06312572 | AN21: 0.11195606 | AO21: 0.09498515 | AP21: 0.04606702 | AQ21: -0.03703619 | AR21: 0.0341979 | AS21: -0.04540668 | AT21: -0.00249291 | AU21: -0.06345533 | AV21: 0.06871391 | AW21: 0.26325492 | AX21: -0.2177183 | AY21: 0.06572229 | AZ21: -0.09305939 | BA21: 0.13959268 | BB21: -0.40443143 | BC21: -0.16446053 | BD21: 0.03821915 | BE21: -0.13674536 | BF21: -0.19911722 | BG21: 0.01324431 | BH21: -0.10684211 | BI21: 0.1659696 | BJ21: 0.02239406 | BK21: 0.08297316 | BL21: 0.14272109 | BM21: 0.04079529 | BN21: 0.02579077 | BO21: -0.17006877 | BP21: 0.03027136 | BQ21: 0.05454223 | BR21: 0.14206146 | BS21: 0.01376079 | BT21: -0.0929522 | BU21: 0.17073851 | BV21: 0.142143 | BW21: 0.40213092 | BX21: 0.08837933 | BY21: 0.01491638 | BZ21: 0.0514982 | CA21: 0.06303215 | CB21: 0.20786985 | CC21: -0.00801895 | CD21: 0.28805606 | CE21: 0.06151488 | CF21: 0.13126568 | CG21: -0.14375119 | CH21: 0.07413708 | CI21: 0.08049962 | CJ21: 0.05514085 | CK21: -0.06715963 | CL21: -0.21045238 | CM21: 0.11623182 | CN21: 0.08085151 | CO21: 0.33548376 | CP21: 0.22270006 | CQ21: 0.02291219 | CR21: 0.23905997 | CS21: -0.0696464 | CT21: 0.08607256 | CU21: -0.06267356 | CV21: 0.13162753 | CW21: -0.03075248 | CX21: 0.10212218 | CY21: 0.15245231 | CZ21: 0.23745137 | DA21: -0.27617087 | DB21: 0.07146121 | DC21: -0.02112899 | DD21: -0.00281879 | DE21: 0.02897774 | DF21: 0.30115021 | DG21: 0.05940952 | DH21: 0.01035557 | DI21: -0.0901492 | DJ21: 0.07330279 | DK21: 0.09089559 | DL21: -0.01273699 | DM21: -0.0249888 | DN21: 0.07119761 | DO21: -0.01855881 | DP21: -0.03710863 | DQ21: 0.12260062 | DR21: -0.11639751 | DS21: -0.00167209 | DT21: 0.1705708 | DU21: 0.14861472 | DV21: 0.14027598 | DW21: -0.10353449 | DX21: 0.18596621 | DY21: 0.16673097 | DZ21: 0.09893057 | EA21: -0.03869399 | EB21: 0.02630219 | EC21: 0.01403706 | ED21: 0.05449886 | EE21: 0.02131059 | EF21: 0.08609767
A22: 321 | B22: 3 | C22: 0.2052803 | D22: 0.14242785 | E22: -0.0173551 | F22: -0.06783106 | G22: 0.23294542 | H22: 0.22980554 | I22: 0.2544329 | J22: 0.05259859 | K22: -0.24536591 | L22: 0.10748717 | M22: 0.07410006 | N22: 0.09803086 | O22: 0.00671588 | P22: -0.04285849 | Q22: -0.08928252 | R22: -0.18067973 | S22: 0.24705663 | T22: 0.0716519 | U22: 0.15202918 | V22: -0.05702413 | W22: 0.15804775 | X22: 0.22178676 | Y22: 0.04793833 | Z22: 0.07554827 | AA22: -0.00704802 | AB22: 0.00386523 | AC22: 0.08577646 | AD22: 0.01357279 | AE22: 0.2483752 | AF22: -0.42991677 | AG22: 0.05284154 | AH22: -0.10586596 | AI22: -0.0673929 | AJ22: 0.04586613 | AK22: 0.10128856 | AL22: -0.00114473 | AM22: -0.05637375 | AN22: 0.11113281 | AO22: 0.19067278 | AP22: 0.06253635 | AQ22: 0.05512672 | AR22: 0.1081837 | AS22: 0.0738437 | AT22: 0.00658039 | AU22: -0.1099146 | AV22: 0.08975398 | AW22: 0.37079928 | AX22: 0.00987519 | AY22: 0.09845628 | AZ22: -0.2274855 | BA22: 0.04977496 | BB22: -0.51826405 | BC22: -0.19562604 | BD22: 0.07925954 | BE22: -0.12806788 | BF22: -0.19910245 | BG22: 0.04627951 | BH22: -0.12770701 | BI22: 0.11108872 | BJ22: 0.04089033 | BK22: 0.02085476 | BL22: 0.16178034 | BM22: 0.00243048 | BN22: 0.0829379 | BO22: -0.0337511 | BP22: -0.00372744 | BQ22: 0.0278301 | BR22: 0.10656678 | BS22: -0.00583862 | BT22: 0.06714322 | BU22: 0.10435058 | BV22: 0.15854397 | BW22: 0.4277165 | BX22: 0.15293737 | BY22: -0.03235288 | BZ22: 0.05632235 | CA22: 0.02749008 | CB22: 0.25473926 | CC22: -0.125104 | CD22: 0.33387804 | CE22: 0.06684015 | CF22: 0.18879979 | CG22: -0.19309653 | CH22: 0.11591877 | CI22: 0.11777975 | CJ22: 0.12632536 | CK22: -0.11092354 | CL22: -0.2406518 | CM22: 0.21983249 | CN22: 0.15280392 | CO22: 0.2720595 | CP22: 0.25940856 | CQ22: 0.01715962 | CR22: 0.24677277 | CS22: 0.01520218 | CT22: 0.12609138 | CU22: -0.11084142 | CV22: 0.1296175 | CW22: -0.0134998 | CX22: 0.00374959 | CY22: 0.16243987 | CZ22: 0.26292048 | DA22: -0.30545166 | DB22: 0.05404162 | DC22: -0.0120564 | DD22: -0.03171017 | DE22: -0.0177565 | DF22: 0.38966763 | DG22: 0.0718895 | DH22: -0.03468875 | DI22: -0.08110554 | DJ22: 0.04277692 | DK22: 0.09142841 | DL22: -0.00321333 | DM22: -0.03188471 | DN22: 0.04676333 | DO22: 0.02376867 | DP22: -0.10509906 | DQ22: 0.131031 | DR22: -0.12963071 | DS22: -0.03634626 | DT22: 0.02637636 | DU22: 0.16154691 | DV22: 0.12570512 | DW22: -0.08141541 | DX22: 0.22244261 | DY22: 0.11995602 | DZ22: 0.1108345 | EA22: -0.07054865 | EB22: 0.12976595 | EC22: 0.0214951 | ED22: 0.07741357 | EE22: 0.04763666 | EF22: 0.03659547
A23: 482 | B23: 2 | C23: 0.28298927 | D23: 0.25409263 | E23: 0.13300519 | F23: -0.18239608 | G23: 0.36163212 | H23: 0.26281024 | I23: 0.25570287 | J23: -0.06164751 | K23: -0.14260758 | L23: 0.23244436 | M23: 0.25844992 | N23: 0.12680001 | O23: 0.01940771 | P23: -0.0106835 | Q23: -0.25084968 | R23: -0.089628 | S23: 0.169295 | T23: 0.00037337 | U23: 0.21298177 | V23: 0.06335701 | W23: 0.25954732 | X23: 0.18178119 | Y23: 0.00758876 | Z23: 0.06213982 | AA23: -0.00660629 | AB23: 0.03099139 | AC23: 0.1687548 | AD23: 0.07162887 | AE23: 0.31087846 | AF23: -0.32465933 | AG23: 0.09187366 | AH23: -0.08417158 | AI23: -0.07545017 | AJ23: -0.01696246 | AK23: 0.1141111 | AL23: -0.05131031 | AM23: 0.02047054 | AN23: 0.2423147 | AO23: 0.34648431 | AP23: -0.0031211 | AQ23: -0.17571221 | AR23: 0.2534608 | AS23: 0.08166362 | AT23: -0.04142772 | AU23: -0.20359589 | AV23: 0.04915007 | AW23: 0.58225997 | AX23: 0.01481278 | AY23: 0.0581396 | AZ23: -0.31598452 | BA23: 0.05399834 | BB23: -0.68602333 | BC23: -0.25286918 | BD23: 0.12597278 | BE23: -0.12429214 | BF23: -0.21000911 | BG23: 0.07476147 | BH23: -0.0633652 | BI23: 0.19111208 | BJ23: 0.05749386 | BK23: 0.00500986 | BL23: 0.1495343 | BM23: -0.06949546 | BN23: 0.03845324 | BO23: 0.00514959 | BP23: 0.03191355 | BQ23: 0.04961184 | BR23: 0.10282259 | BS23: -0.07327539 | BT23: 0.07018926 | BU23: 0.10568527 | BV23: 0.11346757 | BW23: 0.60099753 | BX23: 0.12421952 | BY23: -0.03993945 | BZ23: 0.20232498 | CA23: 0.0756532 | CB23: 0.31616676 | CC23: -0.08454461 | CD23: 0.19167646 | CE23: 0.0596023 | CF23: 0.15713491 | CG23: -0.39324379 | CH23: 0.18019645 | CI23: 0.30989942 | CJ23: 0.1565159 | CK23: -0.07185639 | CL23: -0.40866101 | CM23: 0.23470497 | CN23: 0.27710426 | CO23: 0.26615854 | CP23: 0.31136074 | CQ23: -0.02470227 | CR23: 0.15099817 | CS23: 0.03697422 | CT23: 0.03285022 | CU23: -0.0210566 | CV23: 0.20185146 | CW23: 0.06416511 | CX23: -0.08871699 | CY23: 0.28171083 | CZ23: 0.18199879 | DA23: -0.51777096 | DB23: 0.01874707 | DC23: 0.11919049 | DD23: -0.09279867 | DE23: -0.06008595 | DF23: 0.40879492 | DG23: 0.06762043 | DH23: -0.1095822 | DI23: -0.18491271 | DJ23: -0.03382458 | DK23: 0.09124499 | DL23: 0.02624265 | DM23: -0.04647732 | DN23: 0.0064972 | DO23: -0.08467083 | DP23: -0.0384044 | DQ23: 0.170211 | DR23: -0.12391735 | DS23: -0.11657599 | DT23: 0.12395522 | DU23: 0.05563948 | DV23: 0.27627161 | DW23: 0.02305182 | DX23: 0.31349321 | DY23: -0.05392622 | DZ23: -0.21717399 | EA23: -0.02344891 | EB23: 0.24428466 | EC23: -0.03658432 | ED23: 0.0914259 | EE23: 0.06921208 | EF23: 0.09341586
A24: 964 | B24: 1 | C24: 0.09911336 | D24: 0.10060991 | E24: 0.2845125 | F24: -0.20154572 | G24: 0.22960705 | H24: 0.35082219 | I24: 0.24038624 | J24: -0.09997219 | K24: -0.05044434 | L24: 0.33375944 | M24: 0.14681934 | N24: 0.10519171 | O24: -0.03664879 | P24: -0.07773649 | Q24: 0.09014495 | R24: -0.10836549 | S24: 0.1398838 | T24: -0.12369104 | U24: 0.39296188 | V24: 0.11654032 | W24: -0.16456452 | X24: -0.0361579 | Y24: 0.02939884 | Z24: 0.10584233 | AA24: -0.01354777 | AB24: 0.30039379 | AC24: 0.40174733 | AD24: 0.1011753 | AE24: 0.54125812 | AF24: -0.49538941 | AG24: 0.13313425 | AH24: -0.05669736 | AI24: -0.15191167 | AJ24: -0.02011237 | AK24: 0.08488395 | AL24: -0.10745443 | AM24: -0.01496655 | AN24: 0.22118947 | AO24: 0.08269172 | AP24: 0.02285172 | AQ24: -0.35649193 | AR24: 0.02035084 | AS24: 0.00328677 | AT24: 0.03045921 | AU24: -0.22984102 | AV24: -0.24768466 | AW24: -0.14871096 | AX24: -0.11149134 | AY24: 0.26743574 | AZ24: -0.60989956 | BA24: 0.05049131 | BB24: -0.87270315 | BC24: 0.00436687 | BD24: 0.01863103 | BE24: 0.05738054 | BF24: 0.06437042 | BG24: 0.02683597 | BH24: -0.14767357 | BI24: 0.22362911 | BJ24: 0.19964003 | BK24: 0.01001973 | BL24: 0.31716429 | BM24: 0.08478294 | BN24: 0.10891326 | BO24: -0.20807633 | BP24: -0.16903187 | BQ24: -0.06416963 | BR24: 0.09892089 | BS24: -0.00128472 | BT24: 0.05579926 | BU24: 0.00874849 | BV24: 0.10772845 | BW24: 1.1090121 | BX24: 0.05804337 | BY24: 0.29033687 | BZ24: 0.32032943 | CA24: 0.11522168 | CB24: 0.63969813 | CC24: -0.18246988 | CD24: 0.14430631 | CE24: 0.16556487 | CF24: 0.22172136 | CG24: -0.32381798 | CH24: 0.3542773 | CI24: -0.32845182 | CJ24: 0.30018689 | CK24: -0.32305927 | CL24: 0.14175533 | CM24: 0.63643326 | CN24: 0.6096772 | CO24: 0.45247744 | CP24: 0.1603442 | CQ24: -0.16018965 | CR24: 0.13778746 | CS24: 0.08589523 | CT24: -0.18289659 | CU24: -0.07275135 | CV24: 0.3614803 | CW24: -0.00158814 | CX24: 0.05520719 | CY24: 0.36022805 | CZ24: 0.11220663 | DA24: -0.8130224 | DB24: -0.01650187 | DC24: 0.19117576 | DD24: 0.19584472 | DE24: 0.13158559 | DF24: 0.52558501 | DG24: 0.11954529 | DH24: -0.10283284 | DI24: -0.4230988 | DJ24: 0.02108147 | DK24: 0.11968018 | DL24: 0.06136051 | DM24: -0.00041345 | DN24: 0.23333457 | DO24: -0.08311429 | DP24: -0.14433064 | DQ24: 0.13297735 | DR24: -0.34727417 | DS24: -0.06736255 | DT24: 0.03836287 | DU24: -0.0217814 | DV24: 0.1582247 | DW24: 0.1011825 | DX24: 0.31159313 | DY24: -0.00323988 | DZ24: -0.43350658 | EA24: 0.07735092 | EB24: 0.58969792 | EC24: -0.01430992 | ED24: 0.05617285 | EE24: 0.10748066 | EF24: 0.13408708
A26: 大盤 | B26: TWII | C26: -0.017446771 | D26: 0.020701061 | E26: 0.023982129 | F26: -0.006557579 | G26: 0.03184513 | H26: 0.034348533 | I26: -0.0082549328 | J26: 0.012843524 | K26: -0.051018525 | L26: 0.00087394274 | M26: 0.023389576 | N26: 0.012988972 | O26: 0.0058545887 | P26: 0.027413207 | Q26: -0.0037129361 | R26: 0.024076614 | S26: -0.012190025 | T26: -0.039749578 | U26: -0.07315545 | V26: -0.05826023 | W26: 0.00077279757 | X26: 0.044591521 | Y26: -0.02769968 | Z26: 0.0020950059 | AA26: -0.023400551 | AB26: 0.032129371 | AC26: 0.038903273 | AD26: -0.042865382 | AE26: 0.018647195 | AF26: 0.015229768 | AG26: 0.036016604 | AH26: 0.0093546114 | AI26: 0.010748251 | AJ26: 0.013357754 | AK26: -0.0053327473 | AL26: 0.0013831358 | AM26: 0.020795928 | AN26: 0.031517702 | AO26: 0.0062417165 | AP26: 0.0061452617 | AQ26: 0.016946358 | AR26: 0.03468283 | AS26: 0.0030985886 | AT26: 0.015081347 | AU26: -0.019251209 | AV26: 0.038711513 | AW26: -0.021856951 | AX26: 0.0077743007 | AY26: 0.042397247 | AZ26: -0.026308975 | BA26: 0.0095717493 | BB26: -0.024249741 | BC26: 0.020163374 | BD26: -0.0035049988 | BE26: 0.020151935 | BF26: 0.00058133623 | BG26: -0.005219701 | BH26: -0.11587176 | BI26: 0.0087252257 | BJ26: -0.016377261 | BK26: 0.020840372 | BL26: 0.044975872 | BM26: 0.023954306 | BN26: 0.030239101 | BO26: -0.043725888 | BP26: 0.02188947 | BQ26: 0.0086274303 | BR26: -0.019192954 | BS26: 0.01973513 | BT26: 0.047694337 | BU26: 0.011454817 | BV26: 0.043228621 | BW26: -0.04274743 | BX26: -0.017811292 | BY26: -0.1511531 | BZ26: 0.124224 | CA26: -0.0045572538 | CB26: 0.06021124 | CC26: 0.085992033 | CD26: -0.0058084796 | CE26: -0.006041347 | CF26: 0.0024523244 | CG26: 0.089636252 | CH26: 0.070992733 | CI26: 0.027170643 | CJ26: 0.052468428 | CK26: 0.029480661 | CL26: 0.066825081 | CM26: -0.028772229 | CN26: 0.039462516 | CO26: -0.029031087 | CP26: 0.013983883 | CQ26: -0.032276965 | CR26: 0.0031035766 | CS26: 0.025591856 | CT26: 0.044391886 | CU26: -0.030338959 | CV26: -0.0012579765 | CW26: 0.0023363565 | CX26: -0.064264145 | CY26: 0.012909779 | CZ26: -0.12547709 | DA26: 0.011690683 | DB26: 0.0063378437 | DC26: -0.11730536 | DD26: -0.036010872 | DE26: 0.1389113 | DF26: -0.051143506 | DG26: 0.076731447 | DH26: 0.015508782 | DI26: 0.023223774 | DJ26: -0.018372876 | DK26: 0.062199014 | DL26: 0.020098304 | DM26: 0.01349894 | DN26: -0.030252213 | DO26: -0.017022836 | DP26: -0.021788523 | DQ26: 0.085745625 | DR26: 0.028106744 | DS26: -0.0023031598 | DT26: 0.058471198 | DU26: 0.067658949 | DV26: 0.0050207706 | DW26: 0.037416184 | DX26: 0.084111004 | DY26: -0.036832399 | DZ26: 0.0030917028 | EA26: -0.0019576282 | EB26: 0.026459104 | EC26: -0.024752539 | ED26: 0.034115491 | EE26: 0.021061974 | EF26: -0.020277392

Sheet 預測IC
A1: OLS
B2: Time | C2: 2013/12 | D2: 2014/01 | E2: 2014/02 | F2: 2014/03 | G2: 2014/04 | H2: 2014/05 | I2: 2014/06 | J2: 2014/07 | K2: 2014/08 | L2: 2014/09 | M2: 2014/10 | N2: 2014/11 | O2: 2014/12 | P2: 2015/01 | Q2: 2015/02 | R2: 2015/03 | S2: 2015/04 | T2: 2015/05 | U2: 2015/06 | V2: 2015/07 | W2: 2015/08 | X2: 2015/09 | Y2: 2015/10 | Z2: 2015/11 | AA2: 2015/12 | AB2: 2016/01 | AC2: 2016/02 | AD2: 2016/03 | AE2: 2016/04 | AF2: 2016/05 | AG2: 2016/06 | AH2: 2016/07 | AI2: 2016/08 | AJ2: 2016/09 | AK2: 2016/10 | AL2: 2016/11 | AM2: 2016/12 | AN2: 2017/01 | AO2: 2017/02 | AP2: 2017/03 | AQ2: 2017/04 | AR2: 2017/05 | AS2: 2017/06 | AT2: 2017/07 | AU2: 2017/08 | AV2: 2017/09 | AW2: 2017/10 | AX2: 2017/11 | AY2: 2017/12 | AZ2: 2018/01 | BA2: 2018/02 | BB2: 2018/03 | BC2: 2018/04 | BD2: 2018/05 | BE2: 2018/06 | BF2: 2018/07 | BG2: 2018/08 | BH2: 2018/09 | BI2: 2018/10 | BJ2: 2018/11 | BK2: 2018/12 | BL2: 2019/01 | BM2: 2019/02 | BN2: 2019/03 | BO2: 2019/04 | BP2: 2019/05 | BQ2: 2019/06 | BR2: 2019/07 | BS2: 2019/08 | BT2: 2019/09 | BU2: 2019/10 | BV2: 2019/11 | BW2: 2019/12 | BX2: 2020/01 | BY2: 2020/02 | BZ2: 2020/03 | CA2: 2020/04 | CB2: 2020/05 | CC2: 2020/06 | CD2: 2020/07 | CE2: 2020/08 | CF2: 2020/09 | CG2: 2020/10 | CH2: 2020/11 | CI2: 2020/12 | CJ2: 2021/01 | CK2: 2021/02 | CL2: 2021/03 | CM2: 2021/04 | CN2: 2021/05 | CO2: 2021/06 | CP2: 2021/07 | CQ2: 2021/08 | CR2: 2021/09 | CS2: 2021/10 | CT2: 2021/11 | CU2: 2021/12 | CV2: 2022/01 | CW2: 2022/02 | CX2: 2022/03 | CY2: 2022/04 | CZ2: 2022/05 | DA2: 2022/06 | DB2: 2022/07 | DC2: 2022/08 | DD2: 2022/09 | DE2: 2022/10 | DF2: 2022/11 | DG2: 2022/12 | DH2: 2023/01 | DI2: 2023/02 | DJ2: 2023/03 | DK2: 2023/04 | DL2: 2023/05 | DM2: 2023/06 | DN2: 2023/07 | DO2: 2023/08 | DP2: 2023/09 | DQ2: 2023/10 | DR2: 2023/11 | DS2: 2023/12 | DT2: 2024/01 | DU2: 2024/02 | DV2: 2024/03 | DW2: 2024/04 | DX2: 2024/05 | DY2: 2024/06 | DZ2: 2024/07 | EA2: 2024/08 | EB2: 2024/09 | EC2: 2024/10 | ED2: 2024/11 | EE2: 2024/12 | EF2: 2025/01
B3: bm | C3: 0.036997 | D3: 0.033298 | E3: 0.015422 | F3: 0.016457 | G3: 0.017226 | H3: 0.028764 | I3: 0.024279 | J3: 0.027316 | K3: 0.030174 | L3: 0.025236 | M3: 0.032729 | N3: 0.031555 | O3: 0.034033 | P3: 0.033213 | Q3: 0.029103 | R3: 0.026474 | S3: 0.028295 | T3: 0.022621 | U3: 0.016144 | V3: 0.025033 | W3: 0.045784 | X3: 0.043058 | Y3: 0.037786 | Z3: 0.024097 | AA3: 0.030094 | AB3: 0.028087 | AC3: 0.033771 | AD3: 0.034132 | AE3: 0.034141 | AF3: 0.013118 | AG3: 0.024857 | AH3: 0.031884 | AI3: 0.036386 | AJ3: 0.035949 | AK3: 0.043483 | AL3: 0.038462 | AM3: 0.03941 | AN3: 0.050744 | AO3: 0.053685 | AP3: 0.049315 | AQ3: 0.032774 | AR3: 0.028295 | AS3: 0.028378 | AT3: 0.023069 | AU3: 0.029397 | AV3: 0.031038 | AW3: 0.026298 | AX3: 0.026165 | AY3: 0.032054 | AZ3: 0.034478 | BA3: 0.029332 | BB3: 0.034325 | BC3: 0.037422 | BD3: 0.031414 | BE3: 0.032006 | BF3: 0.028282 | BG3: 0.041103 | BH3: 0.045199 | BI3: 0.041588 | BJ3: 0.040723 | BK3: 0.036328 | BL3: 0.036173 | BM3: 0.037709 | BN3: 0.030814 | BO3: 0.030656 | BP3: 0.0344 | BQ3: 0.034869 | BR3: 0.036324 | BS3: 0.036164 | BT3: 0.038669 | BU3: 0.041103 | BV3: 0.028684 | BW3: 0.035217 | BX3: 0.040767 | BY3: 0.021604 | BZ3: 0.030434 | CA3: 0.037312 | CB3: 0.027612 | CC3: 0.019743 | CD3: 0.007791 | CE3: 0.022527 | CF3: 0.034778 | CG3: 0.032581 | CH3: 0.040909 | CI3: 0.03905 | CJ3: 0.024562 | CK3: 0.034134 | CL3: 0.035926 | CM3: 0.042466 | CN3: 0.036524 | CO3: 0.037659 | CP3: 0.039958 | CQ3: -0.004592 | CR3: 0.015003 | CS3: 0.022459 | CT3: 0.040972 | CU3: 0.038942 | CV3: 0.043015 | CW3: 0.039707 | CX3: 0.039171 | CY3: 0.034941 | CZ3: 0.036027 | DA3: 0.04451 | DB3: 0.039323 | DC3: 0.037933 | DD3: 0.039075 | DE3: 0.041994 | DF3: 0.041965 | DG3: 0.040382 | DH3: 0.036787 | DI3: 0.036878 | DJ3: 0.033682 | DK3: 0.036536 | DL3: 0.031531 | DM3: 0.028662 | DN3: 0.030845 | DO3: 0.033675 | DP3: 0.035102 | DQ3: 0.036708 | DR3: 0.034114 | DS3: 0.036716 | DT3: 0.034828 | DU3: 0.023366 | DV3: 0.025241 | DW3: 0.035159 | DX3: 0.032305 | DY3: 0.023258 | DZ3: 0.028309 | EA3: 0.031397 | EB3: 0.037231 | EC3: 0.033346 | ED3: 0.034187 | EE3: 0.025041 | EF3: 0.034121
B4: size | C4: -0.04966 | D4: -0.064453 | E4: -0.095805 | F4: -0.076694 | G4: -0.026515 | H4: -0.034152 | I4: -0.046191 | J4: -0.046178 | K4: -0.045932 | L4: -0.040812 | M4: -0.018734 | N4: -0.035831 | O4: -0.057023 | P4: -0.042463 | Q4: -0.037772 | R4: -0.028628 | S4: -0.030998 | T4: -0.006704 | U4: -0.037957 | V4: -0.029502 | W4: -0.041243 | X4: -0.054483 | Y4: -0.057374 | Z4: -0.050628 | AA4: -0.04232 | AB4: -0.034274 | AC4: -0.038455 | AD4: -0.032603 | AE4: -0.034795 | AF4: -0.001639 | AG4: -0.032239 | AH4: -0.025693 | AI4: -0.030089 | AJ4: -0.02972 | AK4: -0.022743 | AL4: -0.025322 | AM4: -0.024117 | AN4: -0.027272 | AO4: -0.028383 | AP4: -0.023966 | AQ4: -0.030304 | AR4: -0.017736 | AS4: -0.014939 | AT4: -0.013609 | AU4: -0.016424 | AV4: -0.02404 | AW4: -0.021379 | AX4: -0.023051 | AY4: -0.023942 | AZ4: -0.015978 | BA4: -0.029634 | BB4: -0.036923 | BC4: -0.022612 | BD4: -0.026966 | BE4: -0.030958 | BF4: -0.018182 | BG4: -0.015961 | BH4: -0.021359 | BI4: -0.018896 | BJ4: -0.021053 | BK4: -0.026612 | BL4: -0.017577 | BM4: -0.021846 | BN4: -0.013751 | BO4: -0.006503 | BP4: -0.012172 | BQ4: 0.000223 | BR4: -0.005245 | BS4: -0.012938 | BT4: -0.01635 | BU4: -0.001729 | BV4: 0.015184 | BW4: -0.003769 | BX4: -0.016045 | BY4: -0.018895 | BZ4: -0.004157 | CA4: -0.018224 | CB4: -0.022304 | CC4: -0.041112 | CD4: -0.032535 | CE4: -0.030323 | CF4: -0.061293 | CG4: -0.04417 | CH4: -0.02687 | CI4: -0.017735 | CJ4: -0.011494 | CK4: -0.015911 | CL4: -0.015536 | CM4: -0.019142 | CN4: 0.008031 | CO4: 0.004185 | CP4: -0.007483 | CQ4: -0.000671 | CR4: -0.019179 | CS4: -0.023347 | CT4: -0.021789 | CU4: -0.029507 | CV4: -0.024863 | CW4: -0.022836 | CX4: -0.022236 | CY4: -0.025587 | CZ4: -0.030231 | DA4: -0.043224 | DB4: -0.044725 | DC4: -0.07076 | DD4: -0.05761 | DE4: -0.034042 | DF4: -0.027184 | DG4: -0.035052 | DH4: -0.008428 | DI4: -0.036371 | DJ4: -0.038761 | DK4: -0.027972 | DL4: -0.016271 | DM4: -0.017816 | DN4: -0.008053 | DO4: -0.023536 | DP4: -0.029487 | DQ4: -0.037657 | DR4: -0.029648 | DS4: -0.03019 | DT4: -0.041056 | DU4: -0.037311 | DV4: -0.008939 | DW4: -0.018377 | DX4: -0.030386 | DY4: -0.033049 | DZ4: -0.030982 | EA4: -0.031659 | EB4: -0.036491 | EC4: -0.041069 | ED4: -0.031005 | EE4: -0.023076 | EF4: -0.011421
